Workbook
Name btblfn1: Sheet1!$B$1

Sheet Data
A1: Source | B1: Sample ID | C1: Location | D1: Stratigraphic Unit | E1: Time Period | F1: Age Min (Ma) | G1: Age Max (Ma) | H1: Depth in Column (m) | I1: Sample Type | J1: Lithology | K1: Mineralogy | L1: δ Value | M1: Ca Ratio | N1: Reference Standard | O1: [Sr] | P1: [Sr] Unit | Q1: Sr/Ca | R1: Sr/Ca Unit | S1: δ Value Ref. SW
A2: Tomayo et al.,2018 | B2: PDJ-001 | C2: Great Bank of Guizhou | D2: Dajiang Fm. | E2: Na | F2: 251.9 | G2: 254.14 | H2: 0 | I2: Micrite | J2: PG | K2: Calcite+Dolomite | L2: 0.46586667 | M2: 44/40 | N2: SRM915a | O2: Na | P2: Na | Q2: Na | R2: Na | S2: =IF(NOT(N2="SW"),L2-1.88,L2) -> -1.4141333
A3: Tomayo et al.,2018 | B3: PDJ-009 | C3: Great Bank of Guizhou | D3: Dajiang Fm. | E3: Na | F3: 251.9 | G3: 254.14 | H3: 9 | I3: Micrite | J3: PG | K3: Calcite+Dolomite | L3: 0.40665 | M3: 44/40 | N3: SRM915a | O3: 504 | P3: ppm | Q3: 0.0013448966 | R3: mol/mol | S3: =IF(NOT(N3="SW"),L3-1.88,L3) -> -1.47335
A4: Tomayo et al.,2018 | B4: PDJ-017 | C4: Great Bank of Guizhou | D4: Dajiang Fm. | E4: Na | F4: 251.9 | G4: 254.14 | H4: 17 | I4: Micrite | J4: PG | K4: Calcite+Dolomite | L4: 0.58 | M4: 44/40 | N4: SRM915a | O4: 473.5 | P4: ppm | Q4: 0.0012781752 | R4: mol/mol | S4: =IF(NOT(N4="SW"),L4-1.88,L4) -> -1.3
A5: Tomayo et al.,2018 | B5: PDJ-026 | C5: Great Bank of Guizhou | D5: Dajiang Fm. | E5: Na | F5: 251.9 | G5: 254.14 | H5: 26 | I5: Micrite | J5: PG | K5: Calcite+Dolomite | L5: 0.71 | M5: 44/40 | N5: SRM915a | O5: 432.5 | P5: ppm | Q5: 0.0010849116 | R5: mol/mol | S5: =IF(NOT(N5="SW"),L5-1.88,L5) -> -1.17
A6: Tomayo et al.,2018 | B6: PDJ-030 | C6: Great Bank of Guizhou | D6: Dajiang Fm. | E6: Na | F6: 251.9 | G6: 254.14 | H6: 30 | I6: Micrite | J6: PG | K6: Calcite+Dolomite | L6: 0.29 | M6: 44/40 | N6: SRM915a | O6: 444.5 | P6: ppm | Q6: 0.001155596 | R6: mol/mol | S6: =IF(NOT(N6="SW"),L6-1.88,L6) -> -1.59
A7: Tomayo et al.,2018 | B7: PDJ-033 | C7: Great Bank of Guizhou | D7: Dajiang Fm. | E7: Na | F7: 251.9 | G7: 254.14 | H7: 33 | I7: Micrite | J7: PG | K7: Calcite+Dolomite | L7: 0.44516667 | M7: 44/40 | N7: SRM915a | O7: 445 | P7: ppm | Q7: 0.0012622323 | R7: mol/mol | S7: =IF(NOT(N7="SW"),L7-1.88,L7) -> -1.4348333
A8: Tomayo et al.,2018 | B8: PDJ-040 | C8: Great Bank of Guizhou | D8: Dajiang Fm. | E8: Na | F8: 251.9 | G8: 254.14 | H8: 39.7 | I8: Micrite | J8: PG | K8: Calcite+Dolomite | L8: 0.3486 | M8: 44/40 | N8: SRM915a | O8: 802 | P8: ppm | Q8: 0.0021861796 | R8: mol/mol | S8: =IF(NOT(N8="SW"),L8-1.88,L8) -> -1.5314
A9: Tomayo et al.,2018 | B9: PDJ-044 | C9: Great Bank of Guizhou | D9: Dajiang Fm. | E9: Na | F9: 251.9 | G9: 254.14 | H9: 43 | I9: Micrite | J9: TH | K9: Calcite+Dolomite | L9: 0.23 | M9: 44/40 | N9: SRM915a | O9: 444 | P9: ppm | Q9: 0.0012608264 | R9: mol/mol | S9: =IF(NOT(N9="SW"),L9-1.88,L9) -> -1.65
A10: Tomayo et al.,2018 | B10: PDJ-046 | C10: Great Bank of Guizhou | D10: Dajiang Fm. | E10: Na | F10: 251.9 | G10: 254.14 | H10: 44.5 | I10: Micrite | J10: TH | K10: Calcite+Dolomite | L10: 0.19 | M10: 44/40 | N10: SRM915a | O10: Na | P10: Na | Q10: Na | R10: Na | S10: =IF(NOT(N10="SW"),L10-1.88,L10) -> -1.69
A11: Tomayo et al.,2018 | B11: PDJ-050 | C11: Great Bank of Guizhou | D11: Dajiang Fm. | E11: Na | F11: 251.2 | G11: 251.9 | H11: 47 | I11: Micrite | J11: TH | K11: Calcite+Dolomite | L11: 0.13 | M11: 44/40 | N11: SRM915a | O11: 433 | P11: ppm | Q11: 0.0012430027 | R11: mol/mol | S11: =IF(NOT(N11="SW"),L11-1.88,L11) -> -1.75
A12: Tomayo et al.,2018 | B12: PDJ-053 | C12: Great Bank of Guizhou | D12: Dajiang Fm. | E12: Na | F12: 251.2 | G12: 251.9 | H12: 50 | I12: Micrite | J12: TH | K12: Calcite+Dolomite | L12: 0.08 | M12: 44/40 | N12: SRM915a | O12: Na | P12: Na | Q12: Na | R12: Na | S12: =IF(NOT(N12="SW"),L12-1.88,L12) -> -1.8
A13: Tomayo et al.,2018 | B13: PDJ-055 | C13: Great Bank of Guizhou | D13: Dajiang Fm. | E13: Na | F13: 251.2 | G13: 251.9 | H13: 51.6 | I13: Micrite | J13: TH | K13: Calcite+Dolomite | L13: 0.13075 | M13: 44/40 | N13: SRM915a | O13: 508 | P13: ppm | Q13: 0.0013826892 | R13: mol/mol | S13: =IF(NOT(N13="SW"),L13-1.88,L13) -> -1.74925
A14: Tomayo et al.,2018 | B14: PDJ-058 | C14: Great Bank of Guizhou | D14: Dajiang Fm. | E14: Na | F14: 251.2 | G14: 251.9 | H14: 54 | I14: Micrite | J14: TH | K14: Calcite+Dolomite | L14: 0.26 | M14: 44/40 | N14: SRM915a | O14: 397.5 | P14: ppm | Q14: 0.0012797811 | R14: mol/mol | S14: =IF(NOT(N14="SW"),L14-1.88,L14) -> -1.62
A15: Tomayo et al.,2018 | B15: PDJ-061 | C15: Great Bank of Guizhou | D15: Dajiang Fm. | E15: Na | F15: 251.2 | G15: 251.9 | H15: 56.4 | I15: Micrite | J15: TH | K15: Calcite+Dolomite | L15: 0.2444 | M15: 44/40 | N15: SRM915a | O15: 412 | P15: ppm | Q15: 0.0012875 | R15: mol/mol | S15: =IF(NOT(N15="SW"),L15-1.88,L15) -> -1.6356
A16: Tomayo et al.,2018 | B16: PDJ-064 | C16: Great Bank of Guizhou | D16: Dajiang Fm. | E16: Na | F16: 251.2 | G16: 251.9 | H16: 57.4 | I16: Micrite | J16: TH | K16: Calcite+Dolomite | L16: 0.454 | M16: 44/40 | N16: SRM915a | O16: 478.5 | P16: ppm | Q16: 0.0015462918 | R16: mol/mol | S16: =IF(NOT(N16="SW"),L16-1.88,L16) -> -1.426
A17: Tomayo et al.,2018 | B17: PDJ-068 | C17: Great Bank of Guizhou | D17: Dajiang Fm. | E17: Na | F17: 251.2 | G17: 251.9 | H17: 60 | I17: Micrite | J17: MS | K17: Calcite+Dolomite | L17: 0.13 | M17: 44/40 | N17: SRM915a | O17: 595.5 | P17: ppm | Q17: 0.0017053265 | R17: mol/mol | S17: =IF(NOT(N17="SW"),L17-1.88,L17) -> -1.75
A18: Tomayo et al.,2018 | B18: PDJ-072 | C18: Great Bank of Guizhou | D18: Dajiang Fm. | E18: Na | F18: 251.2 | G18: 251.9 | H18: 64 | I18: Micrite | J18: MS | K18: Calcite+Dolomite | L18: 0.25 | M18: 44/40 | N18: SRM915a | O18: 724 | P18: ppm | Q18: 0.0019556996 | R18: mol/mol | S18: =IF(NOT(N18="SW"),L18-1.88,L18) -> -1.63
A19: Tomayo et al.,2018 | B19: PDJ-075 | C19: Great Bank of Guizhou | D19: Dajiang Fm. | E19: Na | F19: 251.2 | G19: 251.9 | H19: 66 | I19: Micrite | J19: MS | K19: Calcite+Dolomite | L19: 0.17 | M19: 44/40 | N19: SRM915a | O19: 961.5 | P19: ppm | Q19: 0.0026853791 | R19: mol/mol | S19: =IF(NOT(N19="SW"),L19-1.88,L19) -> -1.71
A20: Tomayo et al.,2018 | B20: PDJ-080 | C20: Great Bank of Guizhou | D20: Dajiang Fm. | E20: Na | F20: 251.2 | G20: 251.9 | H20: 70.1 | I20: Micrite | J20: MS | K20: Calcite+Dolomite | L20: 0.23 | M20: 44/40 | N20: SRM915a | O20: 1463 | P20: ppm | Q20: 0.0041164885 | R20: mol/mol | S20: =IF(NOT(N20="SW"),L20-1.88,L20) -> -1.65
A21: Tomayo et al.,2018 | B21: PDJ-081 | C21: Great Bank of Guizhou | D21: Dajiang Fm. | E21: Na | F21: 251.2 | G21: 251.9 | H21: 71 | I21: Micrite | J21: MS | K21: Calcite+Dolomite | L21: 0.21 | M21: 44/40 | N21: SRM915a | O21: 560.5 | P21: ppm | Q21: Na | R21: Na | S21: =IF(NOT(N21="SW"),L21-1.88,L21) -> -1.67
A22: Tomayo et al.,2018 | B22: PDJ-090 | C22: Great Bank of Guizhou | D22: Dajiang Fm. | E22: Na | F22: 251.2 | G22: 251.9 | H22: 80 | I22: Micrite | J22: MS | K22: Calcite+Dolomite | L22: 0.22 | M22: 44/40 | N22: SRM915a | O22: 1451.5 | P22: ppm | Q22: 0.0038227548 | R22: mol/mol | S22: =IF(NOT(N22="SW"),L22-1.88,L22) -> -1.66
A23: Tomayo et al.,2018 | B23: PDJ-100 | C23: Great Bank of Guizhou | D23: Dajiang Fm. | E23: Na | F23: 251.2 | G23: 251.9 | H23: 87.6 | I23: Micrite | J23: MS | K23: Calcite+Dolomite | L23: 0.12 | M23: 44/40 | N23: SRM915a | O23: 315.5 | P23: ppm | Q23: 0.00085990733 | R23: mol/mol | S23: =IF(NOT(N23="SW"),L23-1.88,L23) -> -1.76
A24: Tomayo et al.,2018 | B24: PDJ-107 | C24: Great Bank of Guizhou | D24: Dajiang Fm. | E24: Na | F24: 251.2 | G24: 251.9 | H24: 93.8 | I24: Micrite | J24: MS | K24: Calcite+Dolomite | L24: 0.2 | M24: 44/40 | N24: SRM915a | O24: Na | P24: Na | Q24: Na | R24: Na | S24: =IF(NOT(N24="SW"),L24-1.88,L24) -> -1.68
A25: Tomayo et al.,2018 | B25: PDJ-115 | C25: Great Bank of Guizhou | D25: Dajiang Fm. | E25: Na | F25: 251.2 | G25: 251.9 | H25: 100.4 | I25: Micrite | J25: MS | K25: Calcite+Dolomite | L25: 0.49 | M25: 44/40 | N25: SRM915a | O25: 271 | P25: ppm | Q25: 0.00076770538 | R25: mol/mol | S25: =IF(NOT(N25="SW"),L25-1.88,L25) -> -1.39
A26: Tomayo et al.,2018 | B26: PDJ-118 | C26: Great Bank of Guizhou | D26: Dajiang Fm. | E26: Na | F26: 251.2 | G26: 251.9 | H26: 103 | I26: Micrite | J26: MS | K26: Calcite+Dolomite | L26: 0.58 | M26: 44/40 | N26: SRM915a | O26: Na | P26: Na | Q26: Na | R26: Na | S26: =IF(NOT(N26="SW"),L26-1.88,L26) -> -1.3
A27: Tomayo et al.,2018 | B27: PDJ-127 | C27: Great Bank of Guizhou | D27: Dajiang Fm. | E27: Na | F27: 250.7 | G27: 251.2 | H27: 118.2 | I27: Micrite | J27: MS | K27: Calcite+Dolomite | L27: 0.88 | M27: 44/40 | N27: SRM915a | O27: Na | P27: Na | Q27: Na | R27: Na | S27: =IF(NOT(N27="SW"),L27-1.88,L27) -> -1
A28: Tomayo et al.,2018 | B28: PDJ-132 | C28: Great Bank of Guizhou | D28: Dajiang Fm. | E28: Na | F28: 250.7 | G28: 251.2 | H28: 131 | I28: Micrite | J28: MS | K28: Calcite+Dolomite | L28: 0.77 | M28: 44/40 | N28: SRM915a | O28: Na | P28: Na | Q28: Na | R28: Na | S28: =IF(NOT(N28="SW"),L28-1.88,L28) -> -1.11
A29: Tomayo et al.,2018 | B29: PDJ-140 | C29: Great Bank of Guizhou | D29: Dajiang Fm. | E29: Na | F29: 250.7 | G29: 251.2 | H29: 156.2 | I29: Micrite | J29: OL | K29: Calcite+Dolomite | L29: 0.61405 | M29: 44/40 | N29: SRM915a | O29: 150.5 | P29: ppm | Q29: 0.0007 | R29: mol/mol | S29: =IF(NOT(N29="SW"),L29-1.88,L29) -> -1.26595
A30: Tomayo et al.,2018 | B30: PDJ-148 | C30: Great Bank of Guizhou | D30: Dajiang Fm. | E30: Na | F30: 250.7 | G30: 251.2 | H30: 176 | I30: Micrite | J30: OL | K30: Calcite+Dolomite | L30: 1.0637 | M30: 44/40 | N30: SRM915a | O30: 214.5 | P30: ppm | Q30: 0.00095375723 | R30: mol/mol | S30: =IF(NOT(N30="SW"),L30-1.88,L30) -> -0.8163
A31: Tomayo et al.,2018 | B31: PDJ-162 | C31: Great Bank of Guizhou | D31: Dajiang Fm. | E31: Na | F31: 250.7 | G31: 251.2 | H31: 207.5 | I31: Micrite | J31: PS | K31: Calcite+Dolomite | L31: 0.82 | M31: 44/40 | N31: SRM915a | O31: 597.5 | P31: ppm | Q31: 0.0009 | R31: mol/mol | S31: =IF(NOT(N31="SW"),L31-1.88,L31) -> -1.06
A32: Tomayo et al.,2018 | B32: SQD-9 | C32: Saiq | D32: Saiq Fm. | E32: Na | F32: 250.7 | G32: 251.2 | H32: 198 | I32: Micrite | J32: PS | K32: Calcite+Dolomite | L32: 0.9 | M32: 44/40 | N32: SRM915a | O32: 54 | P32: ppm | Q32: 0.00019533141 | R32: mol/mol | S32: =IF(NOT(N32="SW"),L32-1.88,L32) -> -0.98
A33: Tomayo et al.,2018 | B33: SQD-8 | C33: Saiq | D33: Saiq Fm. | E33: Na | F33: 251.2 | G33: 251.9 | H33: 190 | I33: Micrite | J33: PS | K33: Calcite+Dolomite | L33: 0.95 | M33: 44/40 | N33: SRM915a | O33: 66 | P33: ppm | Q33: 0.00022828969 | R33: mol/mol | S33: =IF(NOT(N33="SW"),L33-1.88,L33) -> -0.93
A34: Tomayo et al.,2018 | B34: SQD-7 | C34: Saiq | D34: Saiq Fm. | E34: Na | F34: 251.2 | G34: 251.9 | H34: 182 | I34: Micrite | J34: PS | K34: Calcite+Dolomite | L34: 1.24 | M34: 44/40 | N34: SRM915a | O34: 77 | P34: ppm | Q34: 0.00024654366 | R34: mol/mol | S34: =IF(NOT(N34="SW"),L34-1.88,L34) -> -0.64
A35: Tomayo et al.,2018 | B35: SQD-6 | C35: Saiq | D35: Saiq Fm. | E35: Na | F35: 251.2 | G35: 251.9 | H35: 174 | I35: Micrite | J35: PS | K35: Calcite+Dolomite | L35: 0.95 | M35: 44/40 | N35: SRM915a | O35: 71.7 | P35: ppm | Q35: 0.0002291148 | R35: mol/mol | S35: =IF(NOT(N35="SW"),L35-1.88,L35) -> -0.93
A36: Tomayo et al.,2018 | B36: SQD 5 | C36: Saiq | D36: Saiq Fm. | E36: Na | F36: 251.2 | G36: 251.9 | H36: 166 | I36: Micrite | J36: PS | K36: Calcite+Dolomite | L36: 0.65 | M36: 44/40 | N36: SRM915a | O36: 71 | P36: ppm | Q36: 0.00020668428 | R36: mol/mol | S36: =IF(NOT(N36="SW"),L36-1.88,L36) -> -1.23
A37: Tomayo et al.,2018 | B37: SQD 4 | C37: Saiq | D37: Saiq Fm. | E37: Na | F37: 251.2 | G37: 251.9 | H37: 158 | I37: Micrite | J37: PS | K37: Calcite+Dolomite | L37: Na | M37: Na | N37: Na | O37: Na | P37: Na | Q37: Na | R37: Na | S37: Na
A38: Tomayo et al.,2018 | B38: SQD-3 | C38: Saiq | D38: Saiq Fm. | E38: Na | F38: 251.2 | G38: 251.9 | H38: 150 | I38: Micrite | J38: PS | K38: Calcite+Dolomite | L38: 0.8 | M38: 44/40 | N38: SRM915a | O38: 72 | P38: ppm | Q38: 0.00022554399 | R38: mol/mol | S38: =IF(NOT(N38="SW"),L38-1.88,L38) -> -1.08
A39: Tomayo et al.,2018 | B39: SQD 2 | C39: Saiq | D39: Saiq Fm. | E39: Na | F39: 251.2 | G39: 251.9 | H39: 143 | I39: Micrite | J39: PS | K39: Calcite+Dolomite | L39: 0.7 | M39: 44/40 | N39: SRM915a | O39: 77 | P39: ppm | Q39: 0.00025412414 | R39: mol/mol | S39: =IF(NOT(N39="SW"),L39-1.88,L39) -> -1.18
A40: Tomayo et al.,2018 | B40: SQD-1 | C40: Saiq | D40: Saiq Fm. | E40: Na | F40: 251.2 | G40: 251.9 | H40: 133 | I40: Micrite | J40: PS | K40: Calcite+Dolomite | L40: 0.85 | M40: 44/40 | N40: SRM915a | O40: 53 | P40: ppm | Q40: 0.00020601413 | R40: mol/mol | S40: =IF(NOT(N40="SW"),L40-1.88,L40) -> -1.03
...

Sheet Legends
B1: Tomayo et al. 2018 | D1: Jost et al. 2017 | G1: Era | H1: End | I1: Start
B2: PG = Packstone-Grainstone | D2: PG = packestone/grainstone | G2: Pliocene-Pleistocene | H2: 0.0117 | I2: 5.33
B3: PS= Packstone | D3: TH = thrombolite | G3: Maastrichtian | H3: 66 | I3: 72.1
B4: Ws= Wackestone | D4: MW = Mudstone/wackestone | G4: Turonian | H4: 89.8 | I4: 93.9
B5: Ms= Mudstone | D5: OL = oolite | G5: Cenomanian | H5: 93.9 | I5: 100.5
B6: Ol= Oolithe | D6: DL = Dolostone | G6: Aptian | H6: 113 | I6: 125
B7: BRCA= Breccia | G7: Barremian | H7: 125 | I7: 129.4
B8: TH=Trombolithe | G8: Hauterivian | H8: 129.4 | I8: 132.9
G9: Valanginian | H9: 132.9 | I9: 139.8
B10: Jones et al. 2020 | G10: Tithonian | H10: 145 | I10: 152.1
B11: ls = Limestone | G11: Kimmeridgian | H11: 149.2 | I11: 154.8
B12: dl = Dolostone | G12: Oxfordian | H12: 157.3 | I12: 163.5
G13: Callovian | H13: 163.5 | I13: 166
G14: Rhaetian | H14: 201.4 | I14: 208.5
G15: Carnian | H15: 227.3 | I15: 237
G16: Ladinian | H16: 237 | I16: 241.464
G17: Anisian | H17: 241.464 | I17: 246.7
G18: Smithian | H18: 249.7 | I18: 250.7
G19: Dinerian | H19: 250.7 | I19: 251.2
G20: Griesbachian | H20: 251.2 | I20: 251.9
G21: Changxingian | H21: 251.9 | I21: 254.14
G22: Permian-Triassic Boundary | H22: 251.9 | I22: 252
G23: Maokouan | H23: 259 | I23: 265
G24: Quixian | H24: 265 | I24: 268
... G88: Ordovician | H88: 443.1 | I88: 486.65

Sheet Sheet1
B2: Stratigraphic Height (m) | C2: δ13C (‰ VPDB) | D2: δ18O (‰ VPDB) | E2: Ca (wt %) | F2: Mg (wt %) | G2: Sr (µg/g rock) | H2: Mn (µg/g rock) | I2: δ44/40Ca (‰ BSE) | J2: δ44/40Ca (‰ SRM-915a) | K2: δ44/40Ca (‰ seawater) | L2: 2σ for δ44/40Ca | M2: n for δ44/40Ca
B3: Val Adrara
B4: 2.8 | C4: 1.87 | D4: −2.14 | E4: 31.6 | F4: 0.66 | G4: 656 | H4: 77 | I4: −0.77 | J4: −1.77 | K4: 0.14 | L4: 0.25 | M4: 3
B5: 9.8 | C5: 2.06 | D5: −2.19 | E5: 31 | F5: 0.57 | G5: 929 | H5: 73 | I5: −0.80 | J5: −1.80 | K5: 0.11 | L5: 0.11 | M5: 2
B6: 20 | C6: 1.36 | D6: −2.26 | E6: 31.3 | F6: 0.67 | G6: 695 | H6: 152 | I6: −0.39 | J6: −1.39 | K6: 0.52 | L6: 0.24 | M6: 2
B7: 30.8 | C7: 1.41 | D7: −3.52 | E7: 29.7 | F7: 0.66 | G7: 378 | H7: 68 | I7: −0.60 | J7: −1.60 | K7: 0.31 | L7: 0.17 | M7: 2
B8: 40 | C8: 2.64 | D8: −1.90 | E8: 32.1 | F8: 0.47 | G8: 1204 | H8: 26 | I8: −0.61 | J8: −1.61 | K8: 0.3 | L8: 0.03 | M8: 2
B9: 46.9 | C9: 2.54 | D9: −2.02 | E9: 31.4 | F9: 0.55 | G9: 727 | H9: 26 | I9: −0.45 | J9: −1.45 | K9: 0.46 | L9: 0.33 | M9: 4
B10: 57 | C10: 2.76 | D10: −2.56 | E10: 33.67 | F10: 0.4 | G10: 2595 | H10: 126 | I10: −0.79 | J10: −1.79 | K10: 0.12 | L10: 0.21 | M10: 3
B11: 57.9 | C11: 3.37 | D11: −1.68 | E11: 34.74 | F11: 0.41 | G11: 2362 | H11: 42 | I11: −1.02 | J11: −2.02 | K11: −0.11 | L11: 0.13 | M11: 2
B12: 64.7 | C12: 3.79 | D12: −2.11 | E12: 32.3 | F12: 0.43 | G12: 2660 | H12: 74 | I12: −1.17 | J12: −2.17 | K12: −0.26 | L12: 0.08 | M12: 2
B13: 66.2 | C13: 3.27 | D13: −3.20 | E13: 35.39 | F13: 0.32 | G13: 2386 | H13: 70 | I13: −1.03 | J13: −2.03 | K13: −0.12 | L13: 0.16 | M13: 2
B14: 67.7 | C14: 3.06 | D14: −2.94 | E14: 32.87 | F14: 0.31 | G14: 2175 | H14: 87 | I14: −1.01 | J14: −2.01 | K14: −0.10 | L14: 0.26 | M14: 5
B15: 71.4 | C15: 3.37 | D15: −2.59 | E15: 33.2 | F15: 0.41 | G15: 1800 | H15: 54 | I15: −1.08 | J15: −2.08 | K15: −0.17 | L15: 0.08 | M15: 2
B16: 79 | C16: 3.03 | D16: −3.40 | E16: 35 | F16: 0.56 | G16: 896 | H16: 29 | I16: −0.39 | J16: −1.39 | K16: 0.52 | L16: 0.25 | M16: 3
B17: 86 | C17: 3.15 | D17: −5.84 | E17: 35.35 | F17: 0.66 | G17: 392 | H17: 13 | I17: −0.51 | J17: −1.51 | K17: 0.4 | L17: 0.13 | M17: 2
B18: 95 | C18: 4.4 | D18: −5.32 | E18: 34.4 | F18: 0.16 | G18: 421 | H18: 7 | I18: −0.51 | J18: −1.51 | K18: 0.4 | L18: 0.08 | M18: 2
B19: 100.6 | C19: 4.36 | D19: −5.68 | E19: 33.5 | F19: 1.29 | G19: 460 | H19: 13 | I19: −0.67 | J19: −1.67 | K19: 0.24 | L19: 0.17 | M19: 2
B20: Italcementi
B21: 7.4 | C21: 2.44 | D21: −1.40 | E21: NA | F21: NA | G21: NA | H21: NA | I21: −0.89 | J21: −1.89 | K21: 0.02 | L21: 0.14 | M21: 2
B22: 23.9 | C22: 2.5 | D22: −1.54 | E22: NA | F22: NA | G22: NA | H22: NA | I22: −0.67 | J22: −1.67 | K22: 0.24 | L22: 0.23 | M22: 3
B23: 35.4 | C23: 2.51 | D23: −1.59 | E23: 20.3 | F23: 0.5 | G23: 507 | H23: 513 | I23: −0.34 | J23: −1.34 | K23: 0.57 | L23: 0.47 | M23: 3
B24: 41.1 | C24: 2.68 | D24: −4.48 | E24: 31.03 | F24: 0.43 | G24: 623 | H24: 21 | I24: −0.51 | J24: −1.51 | K24: 0.4 | L24: 0.01 | M24: 2
B25: 43.1 | C25: 2.42 | D25: −2.91 | E25: 35.98 | F25: 0.3 | G25: 433 | H25: 19 | I25: −0.26 | J25: −1.26 | K25: 0.65 | L25: 0.04 | M25: 2
B26: 45.5 | C26: 2.58 | D26: −1.99 | E26: 35.79 | F26: 0.48 | G26: 341 | H26: 21 | I26: −0.68 | J26: −1.68 | K26: 0.23 | L26: 0.16 | M26: 2
B27: 47.1 | C27: 3.49 | D27: −1.88 | E27: 26.08 | F27: 0.71 | G27: 624 | H27: 111 | I27: −1.05 | J27: −2.05 | K27: −0.14 | L27: 0.11 | M27: 2
B28: 49.9 | C28: NA | D28: NA | E28: 44.43 | F28: 0.59 | G28: 3592 | H28: 85 | I28: −1.08 | J28: −2.08 | K28: −0.17 | L28: 0.06 | M28: 2
B29: 53 | C29: NA | D29: NA | E29: 31.09 | F29: 0.33 | G29: 2173 | H29: 38 | I29: −1.13 | J29: −2.13 | K29: −0.22 | L29: 0.34 | M29: 2
B30: 56.6 | C30: 3.68 | D30: −1.92 | E30: 39.76 | F30: 0.41 | G30: 2531 | H30: 59 | I30: −0.96 | J30: −1.96 | K30: −0.05 | L30: 0.11 | M30: 2
B31: 61 | C31: 3.73 | D31: −2.19 | E31: 39.76 | F31: 0.36 | G31: 1880 | H31: 74 | I31: −0.99 | J31: −1.99 | K31: −0.08 | L31: 0.24 | M31: 2
B32: 65.3 | C32: 3.79 | D32: −2.56 | E32: 31.26 | F32: 0.31 | G32: 1983 | H32: 47 | I32: −0.89 | J32: −1.89 | K32: 0.02 | L32: 0.23 | M32: 3
B33: 72.9 | C33: 3.35 | D33: −2.14 | E33: 30.44 | F33: 0.31 | G33: 2087 | H33: 50 | I33: −0.70 | J33: −1.70 | K33: 0.21 | L33: 0.07 | M33: 2
B34: 77 | C34: 3.66 | D34: −2.05 | E34: 35.67 | F34: 0.59 | G34: 1257 | H34: 25 | I34: −0.80 | J34: −1.80 | K34: 0.11 | L34: 0.35 | M34: 2
B35: 86.5 | C35: 3.83 | D35: −2.58 | E35: 35.76 | F35: 0.45 | G35: 687 | H35: 15 | I35: −0.46 | J35: −1.46 | K35: 0.45 | L35: 0.18 | M35: 2
B36: 93 | C36: 3.93 | D36: −3.97 | E36: 36.52 | F36: 0.37 | G36: 543 | H36: 13 | I36: −0.53 | J36: −1.53 | K36: 0.38 | L36: 0 | M36: 2
B37: 98.3 | C37: 3.88 | D37: −6.70 | E37: 34.89 | F37: 0.37 | G37: 748 | H37: 7 | I37: −0.68 | J37: −1.68 | K37: 0.23 | L37: 0.24 | M37: 2
